# try_catch_error_in_python